<?xml version="1.0" ?>
<!-- =================================================================================== -->
<!-- |    This document was autogenerated by xacro from /home/alice/ERL_WS/src/assignment2/urdf/robotA.urdf.xacro | -->
<!-- |    EDITING THIS FILE BY HAND IS NOT RECOMMENDED                                 | -->
<!-- =================================================================================== -->
<robot name="A">
    <!-- Z axis -->
    <!-- Material -->
    <material name="black">
        <color rgba="0.0 0.0 0.0 1.0" />
    </material>
    <material name="blue">
        <color rgba="0.203125 0.23828125 0.28515625 1.0" />
    </material>
    <material name="red">
        <color rgba="0.80078125 0.12890625 0.1328125 1.0" />
    </material>
    <material name="white">
        <color rgba="1.0 1.0 1.0 1.0" />
    </material>
    <!-- BASE -->
    <link name="base_link" />
    <!-- Chassis -->
    <link name="chassis">
        <visual>
            <geometry>
                <box size="0.4 0.3 0.1" />
            </geometry>
            <material name="blue" />
        </visual>
        <collision>
            <geometry>
                <box size="0.4 0.3 0.1" />
            </geometry>
        </collision>
        
<inertial>
            <mass value="0.5" />
            <inertia ixx="0.004166666666666667" ixy="0.0" ixz="0.0" iyy="0.007083333333333335" iyz="0.0" izz="0.010416666666666666" />
        </inertial>

    </link>
    <joint name="chassis_joint" type="fixed">
        <parent link="base_link" />
        <child link="chassis" />
    </joint>
    <gazebo reference="chassis">
        <material>Gazebo/White</material>
    </gazebo>
    <link name="front_left_wheel">
        <visual>
            <origin rpy="1.5707963267948966 0 0" xyz="0 0 0" />
            <geometry>
                <cylinder length="0.05" radius="0.1" />
            </geometry>
            <material name="black" />
        </visual>
        <collision>
            <origin rpy="1.5707963267948966 0 0" xyz="0 0 0" />
            <geometry>
                <cylinder length="0.05" radius="0.1" />
            </geometry>
        </collision>
        
<inertial>
            <mass value="0.1" />
            <inertia ixx="0.0002708333333333334" ixy="0.0" ixz="0.0" iyy="0.0002708333333333334" iyz="0.0" izz="0.0005000000000000001" />
        </inertial>

    </link>
    <joint name="front_left_wheel_joint" type="continuous">
        <axis rpy="0 0 0" xyz="0 1 0" />
        <parent link="chassis" />
        <child link="front_left_wheel" />
        <origin rpy="0 0 0" xyz="0.12 0.1925 0" />
        <dynamics damping="0" />
    </joint>
    <gazebo reference="front_left_wheel">
        <!-- <mu1 value="200.0"/>
      <mu2 value="100.0"/>
      <kp value="10000000.0" />
      <kd value="1.0" /> -->
        <material>Gazebo/DarkGray</material>
    </gazebo>
    <transmission name="front_left_wheel_trans">
        <type>transmission_interface/SimpleTransmission</type>
        <joint name="front_left_wheel_joint">
            <!-- Needed for ros deifferential drive controller -->
            <!-- <hardwareInterface>hardware_interface/VelocityJointInterface</hardwareInterface> -->
            <!-- Needed for gazebo differential drive controller -->
            <hardwareInterface>hardware_interface/EffortJointInterface</hardwareInterface>
        </joint>
        <actuator name="front_left_wheel_motor">
            <!-- Needed for ros deifferential drive controller -->
            <!-- <hardwareInterface>hardware_interface/VelocityJointInterface</hardwareInterface> -->
            <!-- Needed for gazebo differential drive controller -->
            <hardwareInterface>hardware_interface/EffortJointInterface</hardwareInterface>
            <mechanicalReduction>1</mechanicalReduction>
        </actuator>
    </transmission>
    <link name="front_right_wheel">
        <visual>
            <origin rpy="1.5707963267948966 0 0" xyz="0 0 0" />
            <geometry>
                <cylinder length="0.05" radius="0.1" />
            </geometry>
            <material name="black" />
        </visual>
        <collision>
            <origin rpy="1.5707963267948966 0 0" xyz="0 0 0" />
            <geometry>
                <cylinder length="0.05" radius="0.1" />
            </geometry>
        </collision>
        
<inertial>
            <mass value="0.1" />
            <inertia ixx="0.0002708333333333334" ixy="0.0" ixz="0.0" iyy="0.0002708333333333334" iyz="0.0" izz="0.0005000000000000001" />
        </inertial>

    </link>
    <joint name="front_right_wheel_joint" type="continuous">
        <axis rpy="0 0 0" xyz="0 1 0" />
        <parent link="chassis" />
        <child link="front_right_wheel" />
        <origin rpy="0 0 0" xyz="0.12 -0.1925 0" />
        <dynamics damping="0" />
    </joint>
    <gazebo reference="front_right_wheel">
        <!-- <mu1 value="200.0"/>
      <mu2 value="100.0"/>
      <kp value="10000000.0" />
      <kd value="1.0" /> -->
        <material>Gazebo/DarkGray</material>
    </gazebo>
    <transmission name="front_right_wheel_trans">
        <type>transmission_interface/SimpleTransmission</type>
        <joint name="front_right_wheel_joint">
            <!-- Needed for ros deifferential drive controller -->
            <!-- <hardwareInterface>hardware_interface/VelocityJointInterface</hardwareInterface> -->
            <!-- Needed for gazebo differential drive controller -->
            <hardwareInterface>hardware_interface/EffortJointInterface</hardwareInterface>
        </joint>
        <actuator name="front_right_wheel_motor">
            <!-- Needed for ros deifferential drive controller -->
            <!-- <hardwareInterface>hardware_interface/VelocityJointInterface</hardwareInterface> -->
            <!-- Needed for gazebo differential drive controller -->
            <hardwareInterface>hardware_interface/EffortJointInterface</hardwareInterface>
            <mechanicalReduction>1</mechanicalReduction>
        </actuator>
    </transmission>
    <link name="back_left_wheel">
        <visual>
            <origin rpy="1.5707963267948966 0 0" xyz="0 0 0" />
            <geometry>
                <cylinder length="0.05" radius="0.1" />
            </geometry>
            <material name="black" />
        </visual>
        <collision>
            <origin rpy="1.5707963267948966 0 0" xyz="0 0 0" />
            <geometry>
                <cylinder length="0.05" radius="0.1" />
            </geometry>
        </collision>
        
<inertial>
            <mass value="0.1" />
            <inertia ixx="0.0002708333333333334" ixy="0.0" ixz="0.0" iyy="0.0002708333333333334" iyz="0.0" izz="0.0005000000000000001" />
        </inertial>

    </link>
    <joint name="back_left_wheel_joint" type="continuous">
        <axis rpy="0 0 0" xyz="0 1 0" />
        <parent link="chassis" />
        <child link="back_left_wheel" />
        <origin rpy="0 0 0" xyz="-0.12 0.1925 0" />
        <dynamics damping="0" />
    </joint>
    <gazebo reference="back_left_wheel">
        <!-- <mu1 value="200.0"/>
      <mu2 value="100.0"/>
      <kp value="10000000.0" />
      <kd value="1.0" /> -->
        <material>Gazebo/DarkGray</material>
    </gazebo>
    <transmission name="back_left_wheel_trans">
        <type>transmission_interface/SimpleTransmission</type>
        <joint name="back_left_wheel_joint">
            <!-- Needed for ros deifferential drive controller -->
            <!-- <hardwareInterface>hardware_interface/VelocityJointInterface</hardwareInterface> -->
            <!-- Needed for gazebo differential drive controller -->
            <hardwareInterface>hardware_interface/EffortJointInterface</hardwareInterface>
        </joint>
        <actuator name="back_left_wheel_motor">
            <!-- Needed for ros deifferential drive controller -->
            <!-- <hardwareInterface>hardware_interface/VelocityJointInterface</hardwareInterface> -->
            <!-- Needed for gazebo differential drive controller -->
            <hardwareInterface>hardware_interface/EffortJointInterface</hardwareInterface>
            <mechanicalReduction>1</mechanicalReduction>
        </actuator>
    </transmission>
    <link name="back_right_wheel">
        <visual>
            <origin rpy="1.5707963267948966 0 0" xyz="0 0 0" />
            <geometry>
                <cylinder length="0.05" radius="0.1" />
            </geometry>
            <material name="black" />
        </visual>
        <collision>
            <origin rpy="1.5707963267948966 0 0" xyz="0 0 0" />
            <geometry>
                <cylinder length="0.05" radius="0.1" />
            </geometry>
        </collision>
        
<inertial>
            <mass value="0.1" />
            <inertia ixx="0.0002708333333333334" ixy="0.0" ixz="0.0" iyy="0.0002708333333333334" iyz="0.0" izz="0.0005000000000000001" />
        </inertial>

    </link>
    <joint name="back_right_wheel_joint" type="continuous">
        <axis rpy="0 0 0" xyz="0 1 0" />
        <parent link="chassis" />
        <child link="back_right_wheel" />
        <origin rpy="0 0 0" xyz="-0.12 -0.1925 0" />
        <dynamics damping="0" />
    </joint>
    <gazebo reference="back_right_wheel">
        <!-- <mu1 value="200.0"/>
      <mu2 value="100.0"/>
      <kp value="10000000.0" />
      <kd value="1.0" /> -->
        <material>Gazebo/DarkGray</material>
    </gazebo>
    <transmission name="back_right_wheel_trans">
        <type>transmission_interface/SimpleTransmission</type>
        <joint name="back_right_wheel_joint">
            <!-- Needed for ros deifferential drive controller -->
            <!-- <hardwareInterface>hardware_interface/VelocityJointInterface</hardwareInterface> -->
            <!-- Needed for gazebo differential drive controller -->
            <hardwareInterface>hardware_interface/EffortJointInterface</hardwareInterface>
        </joint>
        <actuator name="back_right_wheel_motor">
            <!-- Needed for ros deifferential drive controller -->
            <!-- <hardwareInterface>hardware_interface/VelocityJointInterface</hardwareInterface> -->
            <!-- Needed for gazebo differential drive controller -->
            <hardwareInterface>hardware_interface/EffortJointInterface</hardwareInterface>
            <mechanicalReduction>1</mechanicalReduction>
        </actuator>
    </transmission>
    <!-- Arm-Chassis -->
    <link name="arm_chassis">
        
<inertial>
            <mass value="0.1" />
            <origin rpy="0 0 0" xyz="0 0 0" />
            <inertia ixx="0.0000416666667" ixy="0" ixz="0" iyy="0.0000416666667" iyz="0" izz="0.0000416666667" />
        </inertial>

        <collision>
            <origin rpy="0 0 0" xyz="0 0 0" />
            <geometry>
                <box size="0.15 0.15 0.03" />
            </geometry>
        </collision>
        <visual>
            <origin rpy="0 0 0" xyz="0 0 0" />
            <geometry>
                <box size="0.15 0.15 0.03" />
            </geometry>
            <material name="red" />
        </visual>
    </link>
    <joint name="arm_chassis_joint" type="fixed">
        <axis xyz="0 0 1" />
        <origin rpy="0 0 0" xyz="0 0 0.08" />
        <parent link="chassis" />
        <child link="arm_chassis" />
    </joint>
    <gazebo reference="arm_chassis">
        <material>Gazebo/Red</material>
    </gazebo>
    <link name="arm_1">
        <visual>
            <origin rpy="0 0 0" xyz="0 0 0.15" />
            <geometry>
                <cylinder length="0.3" radius="0.04" />
            </geometry>
            <material name="red" />
        </visual>
        <collision>
            <origin rpy="0 0 0" xyz="0 0 0.15" />
            <geometry>
                <cylinder length="0.2" radius="0.04" />
            </geometry>
        </collision>
        
<inertial>
            <mass value="0.01" />
            <inertia ixx="0.000010279" ixy="0.0" ixz="0.0" iyy="0.000010279" iyz="0.0" izz="0.000007225" />
        </inertial>

    </link>
    <gazebo reference="arm_1">
        <material>Gazebo/Red</material>
    </gazebo>
    <transmission name="arm_1_trans">
        <type>transmission_interface/SimpleTransmission</type>
        <joint name="arm_1_joint">
            <hardwareInterface>hardware_interface/EffortJointInterface</hardwareInterface>
        </joint>
        <actuator name="arm_1_motor">
            <hardwareInterface>hardware_interface/EffortJointInterface</hardwareInterface>
            <mechanicalInterface>1</mechanicalInterface>
        </actuator>
    </transmission>
    <!-- posz = 0 0 0 ???? -->
    <joint name="arm_1_joint" type="revolute">
        <axis xyz="0 1 0" />
        <limit effort="1000.0" lower="-1.8" upper="1.8" velocity="0.2" />
        <origin rpy="0 0 0" xyz="0 0 0.015" />
        <parent link="arm_chassis" />
        <child link="arm_1" />
    </joint>
    <link name="arm_2">
        <visual>
            <origin rpy="0 0 0" xyz="0 0 0.15" />
            <geometry>
                <cylinder length="0.3" radius="0.04" />
            </geometry>
            <material name="red" />
        </visual>
        <collision>
            <origin rpy="0 0 0" xyz="0 0 0.15" />
            <geometry>
                <cylinder length="0.2" radius="0.04" />
            </geometry>
        </collision>
        
<inertial>
            <mass value="0.01" />
            <inertia ixx="0.000010279" ixy="0.0" ixz="0.0" iyy="0.000010279" iyz="0.0" izz="0.000007225" />
        </inertial>

    </link>
    <gazebo reference="arm_2">
        <material>Gazebo/Red</material>
    </gazebo>
    <transmission name="arm_2_trans">
        <type>transmission_interface/SimpleTransmission</type>
        <joint name="arm_2_joint">
            <hardwareInterface>hardware_interface/EffortJointInterface</hardwareInterface>
        </joint>
        <actuator name="arm_2_motor">
            <hardwareInterface>hardware_interface/EffortJointInterface</hardwareInterface>
            <mechanicalInterface>1</mechanicalInterface>
        </actuator>
    </transmission>
    <joint name="arm_2_joint" type="revolute">
        <axis xyz="0 1 0" />
        <limit effort="1000.0" lower="-1.8" upper="1.8" velocity="0.2" />
        <origin rpy="0 0 0" xyz="0 0 0.3" />
        <parent link="arm_1" />
        <child link="arm_2" />
    </joint>
    <link name="LaserScan">
        <collision>
            <origin rpy="0 0 0" xyz="0 0 0" />
            <geometry>
                <cylinder length="0.04" radius="0.04" />
            </geometry>
        </collision>
        <visual>
            <origin rpy="0 0 0" xyz="0 0 0" />
            <geometry>
                <cylinder length="0.04" radius="0.04" />
            </geometry>
        </visual>
        <!--       
<inertial>
        <mass value="0.01" />
        <origin xyz="0 0 0" rpy="0 0 0"/>
        <inertia ixx="5.3e-8" ixy="0" ixz="0" iyy="6.7e-9" iyz="0" izz="6.7e-9" />
      </inertial>
 -->
        
<inertial>
            <mass value="0.1" />
            <inertia ixx="0.03" iyy="0.03" izz="0.03" ixy="0.0" ixz="0.0" iyz="0.0" />
        </inertial>

    </link>
    <joint name="LaserScan_joint" type="fixed">
        <axis xyz="0 0 1" />
        <origin rpy="0 0 0" xyz="0.2 0 0.07500000000000001" />
        <parent link="chassis" />
        <child link="LaserScan" />
    </joint>
    <gazebo reference="LaserScan">
        <sensor name="LaserScan" type="ray">
            <pose>0 0 0 0 0 0</pose>
            <visualize>true</visualize>
            <update_rate>40</update_rate>
            <ray>
                <scan>
                    <horizontal>
                        <samples>720</samples>
                        <resolution>1</resolution>
                        <min_angle>-1.570796</min_angle>
                        <max_angle>1.570796</max_angle>
                    </horizontal>
                </scan>
                <range>
                    <min>0.10</min>
                    <max>30.0</max>
                    <resolution>0.01</resolution>
                </range>
                <noise>
                    <type>gaussian</type>
                    <!-- Noise parameters based on published spec for Hokuyo laser
                achieving "+-30mm" accuracy at range < 10m.  A mean of 0.0m and
                stddev of 0.01m will put 99.7% of samples within 0.03m of the true
                reading. -->
                    <mean>0.0</mean>
                    <stddev>0.01</stddev>
                </noise>
            </ray>
            <plugin filename="libgazebo_ros_laser.so" name="laser_scanner_controller">
                <topicName>/scan</topicName>
                <frameName>LaserScan</frameName>
            </plugin>
        </sensor>
    </gazebo>
    <link name="RGB">
        <collision>
            <origin rpy="0 0 0" xyz="0 0 0" />
            <geometry>
                <box size="0.08 0.08 0.08" />
            </geometry>
        </collision>
        <visual>
            <origin rpy="0 0 0" xyz="0 0 0" />
            <geometry>
                <box size="0.08 0.08 0.08" />
            </geometry>
        </visual>
        <!-- 
<inertial>
        <mass value="0.01" />
        <origin xyz="0 0 0" rpy="0 0 0"/>
        <inertia ixx="5.3e-8" ixy="0" ixz="0" iyy="6.7e-9" iyz="0" izz="6.7e-9" />
      </inertial>
 -->
        
<inertial>
            <mass value="0.1" />
            <inertia ixx="0.03" iyy="0.03" izz="0.03" ixy="0.0" ixz="0.0" iyz="0.0" />
        </inertial>

    </link>
    <joint name="RGB_joint" type="continuous">
        <axis xyz="0 0 1" />
        <origin rpy="0 0 0" xyz="0 0 0.34" />
        <parent link="arm_2" />
        <child link="RGB" />
    </joint>
    <gazebo reference="RGB">
        <sensor name="RGB" type="camera">
            <update_rate>30.0</update_rate>
            <camera name="RGB">
                <horizontal_fov>1.3962634</horizontal_fov>
                <image>
                    <width>800</width>
                    <height>800</height>
                    <format>R8G8B8</format>
                </image>
                <clip>
                    <near>0.02</near>
                    <far>300</far>
                </clip>
                <noise>
                    <type>gaussian</type>
                    <mean>0.0</mean>
                    <stddev>0.007</stddev>
                </noise>
            </camera>
            <plugin filename="libgazebo_ros_camera.so" name="rgb_camera_controller">
                <alwaysOn>true</alwaysOn>
                <updateRate>0.0</updateRate>
                <cameraName>RGB</cameraName>
                <imageTopicName>RGB/image_raw</imageTopicName>
                <cameraInfoTopicName>RGB/camera_info</cameraInfoTopicName>
                <frameName>RGB</frameName>
                <hackBaseline>0.07</hackBaseline>
                <distortionK1>0.0</distortionK1>
                <distortionK2>0.0</distortionK2>
                <distortionK3>0.0</distortionK3>
                <distortionT1>0.0</distortionT1>
                <distortionT2>0.0</distortionT2>
            </plugin>
        </sensor>
        <material>Gazebo/Blue</material>
    </gazebo>
    <transmission name="RGB_trans">
        <type>transmission_interface/SimpleTransmission</type>
        <joint name="RGB_joint">
            <hardwareInterface>hardware_interface/EffortJointInterface</hardwareInterface>
        </joint>
        <actuator name="RGB_motor">
            <hardwareInterface>hardware_interface/EffortJointInterface</hardwareInterface>
            <mechanicalReduction>1</mechanicalReduction>
        </actuator>
    </transmission>
    <!-- GAZEBO Plugins -->
    <!-- Skid Steer Drive Controller-->
    <gazebo>
        <plugin filename="libgazebo_ros_skid_steer_drive.so" name="mobile_base_controller">
            <updateRate>100.0</updateRate>
            <robotNamespace>/A</robotNamespace>
            <leftFrontJoint>front_left_wheel_joint</leftFrontJoint>
            <rightFrontJoint>front_right_wheel_joint</rightFrontJoint>
            <leftRearJoint>back_left_wheel_joint</leftRearJoint>
            <rightRearJoint>back_right_wheel_joint</rightRearJoint>
            <wheelSeparation>0.264</wheelSeparation>
            <wheelDiameter>0.1*2</wheelDiameter>
            <robotBaseFrame>base_link</robotBaseFrame>
            <!-- Maximum torque which the wheels can produce, in Nm -->
            <torque>20</torque>
            <!-- Topic to receive geometry_msgs/Twist message commands, defaults to `cmd_vel` -->
            <commandTopic>/cmd_vel</commandTopic>
            <!-- Topic to publish nav_msgs/Odometry messages, defaults to `odom` -->
            <odometryTopic>/odom</odometryTopic>
            <!-- Odometry frame, defaults to `odom` -->
            <odometryFrame>odom</odometryFrame>
            <odometryRate>20.0</odometryRate>
            <covariance_x>100.0</covariance_x>
            <covariance_y>100.0</covariance_y>
            <covariance_yaw>100.0</covariance_yaw>
            <broadcastTF>true</broadcastTF>
        </plugin>
    </gazebo>
    <!-- Force/Torque Sensor
    <gazebo reference="arm_${number}_joint">
      <provideFeedback>true</provideFeedback>
    </gazebo>

    <gazebo>
      <plugin name="ft_sensor" filename="libgazebo_ros_ft_sensor.so">
        <updateRate>100.0</updateRate>
        <topicName>ft_sensor_topic</topicName>
        <jointName>arm_${number}_joint</jointName>
      </plugin>
    </gazebo> -->
    <!-- ROS Control -->
    <gazebo>
        <plugin filename="libgazebo_ros_control.so" name="gazebo_ros_control">
            <robotNamespace>/A</robotNamespace>
            <legacyModeNS>true</legacyModeNS>
            <robotSimType>gazebo_ros_control/DefaultRobotHWSim</robotSimType>
        </plugin>
    </gazebo>
    <transmission name="trans_front_left_wheel_joint">
        <type>transmission_interface/SimpleTransmission</type>
        <joint name="front_left_wheel_joint">
            <hardwareInterface>hardware_interface/EffortJointInterface</hardwareInterface>
        </joint>
        <actuator name="front_left_wheel_joint_motor">
            <hardwareInterface>hardware_interface/EffortJointInterface</hardwareInterface>
            <mechanicalReduction>1</mechanicalReduction>
        </actuator>
    </transmission>
    <transmission name="trans_front_right_wheel_joint">
        <type>transmission_interface/SimpleTransmission</type>
        <joint name="front_right_wheel_joint">
            <hardwareInterface>hardware_interface/EffortJointInterface</hardwareInterface>
        </joint>
        <actuator name="front_right_wheel_joint_motor">
            <hardwareInterface>hardware_interface/EffortJointInterface</hardwareInterface>
            <mechanicalReduction>1</mechanicalReduction>
        </actuator>
    </transmission>
    <transmission name="trans_back_left_wheel_joint">
        <type>transmission_interface/SimpleTransmission</type>
        <joint name="back_left_wheel_joint">
            <hardwareInterface>hardware_interface/EffortJointInterface</hardwareInterface>
        </joint>
        <actuator name="back_left_wheel_joint_motor">
            <hardwareInterface>hardware_interface/EffortJointInterface</hardwareInterface>
            <mechanicalReduction>1</mechanicalReduction>
        </actuator>
    </transmission>
    <transmission name="trans_back_right_wheel_joint">
        <type>transmission_interface/SimpleTransmission</type>
        <joint name="back_right_wheel_joint">
            <hardwareInterface>hardware_interface/EffortJointInterface</hardwareInterface>
        </joint>
        <actuator name="back_right_wheel_joint_motor">
            <hardwareInterface>hardware_interface/EffortJointInterface</hardwareInterface>
            <mechanicalReduction>1</mechanicalReduction>
        </actuator>
    </transmission>
    <transmission name="trans_arm_1_joint">
        <type>transmission_interface/SimpleTransmission</type>
        <joint name="arm_1_joint">
            <hardwareInterface>hardware_interface/EffortJointInterface</hardwareInterface>
        </joint>
        <actuator name="arm_1_joint_motor">
            <hardwareInterface>hardware_interface/EffortJointInterface</hardwareInterface>
            <mechanicalReduction>1</mechanicalReduction>
        </actuator>
    </transmission>
    <transmission name="trans_arm_2_joint">
        <type>transmission_interface/SimpleTransmission</type>
        <joint name="arm_2_joint">
            <hardwareInterface>hardware_interface/EffortJointInterface</hardwareInterface>
        </joint>
        <actuator name="arm_2_joint_motor">
            <hardwareInterface>hardware_interface/EffortJointInterface</hardwareInterface>
            <mechanicalReduction>1</mechanicalReduction>
        </actuator>
    </transmission>
    <transmission name="trans_RGB_joint">
        <type>transmission_interface/SimpleTransmission</type>
        <joint name="RGB_joint">
            <hardwareInterface>hardware_interface/EffortJointInterface</hardwareInterface>
        </joint>
        <actuator name="RGB_joint_motor">
            <hardwareInterface>hardware_interface/EffortJointInterface</hardwareInterface>
            <mechanicalReduction>1</mechanicalReduction>
        </actuator>
    </transmission>
    <gazebo>
        <plugin name="gazebo_ros_control" filename="libgazebo_ros_control.so">
            <robotNamespace>/</robotNamespace>
        </plugin>
    </gazebo>
</robot>